Workbook

Sheet Overview
A1: Quiz Calibration Workbook
A3: How to use
A4: 1) Go to a quiz sheet (Quiz 1 … Quiz 15).
A5: 2) Adjust Total Questions and per-set Weights (blue text / yellow fill).
A6: 3) Review weight share, expected question counts, expected correct counts.
A7: 4) Pass threshold is derived from expected correct at Ability = Quiz Level.
A8: 5) P values show estimated pass probability at Ability n-1, n-0.5, n, n+0.5 (normal approximation).
A11: Color legend
A12: Input cells (change these) | B12: Calculated cells (formulas)
A14: Quiz scopes
A15: Quiz Level | B15: Scope (S sets) | C15: Scope (L sets) | D15: Link
A16: 1 | B16: S0–S1 | C16: L2–L2 | D16: Go to Quiz 1
A17: 2 | B17: S0–S3 | C17: L2–L4 | D17: Go to Quiz 2
A18: 3 | B18: S1–S4 | C18: L3–L5 | D18: Go to Quiz 3
A19: 4 | B19: S2–S6 | C19: L4–L6 | D19: Go to Quiz 4
A20: 5 | B20: S3–S7 | C20: L5–L7 | D20: Go to Quiz 5
A21: 6 | B21: S4–S9 | C21: L6–L8 | D21: Go to Quiz 6
A22: 7 | B22: S6–S11 | C22: L7–L9 | D22: Go to Quiz 7
A23: 8 | B23: S6–S13 | C23: L8–L10 | D23: Go to Quiz 8
A24: 9 | B24: S7–S14 | C24: L9–L11 | D24: Go to Quiz 9
A25: 10 | B25: S8–S15 | C25: L10–L12 | D25: Go to Quiz 10
A26: 11 | B26: S8–S15 | C26: L11–L13 | D26: Go to Quiz 11
A27: 12 | B27: S8–S15 | C27: L12–L14 | D27: Go to Quiz 12
... A30: 15 | B30: S8–S15 | C30: L13–L15 | D30: Go to Quiz 15

Sheet AccuracyTable
A1: items | B1: set | C1: 0.5 | D1: 1 | E1: 1.5 | F1: 2 | G1: 2.5 | H1: 3 | I1: 3.5 | J1: 4 | K1: 4.5 | L1: 5 | M1: 5.5 | N1: 6 | O1: 6.5 | P1: 7 | Q1: 7.5 | R1: 8 | S1: 8.5 | T1: 9 | U1: 9.5 | V1: 10 | W1: 10.5 | X1: 11 | Y1: 11.5 | Z1: 12 | AA1: 12.5 | AB1: 13 | AC1: 13.5 | AD1: 14 | AE1: 14.5 | AF1: 15
A2: 15 | B2: S0 | C2: 0.4815 | D2: 0.7126 | E2: 0.8726 | F2: 0.9394 | G2: 0.9498 | H2: 0.95 | I2: 0.95 | J2: 0.95 | K2: 0.95 | L2: 0.95 | M2: 0.95 | N2: 0.95 | O2: 0.95 | P2: 0.95 | Q2: 0.95 | R2: 0.95 | S2: 0.95 | T2: 0.95 | U2: 0.95 | V2: 0.95 | W2: 0.95 | X2: 0.95 | Y2: 0.95 | Z2: 0.95 | AA2: 0.95 | AB2: 0.95 | AC2: 0.95 | AD2: 0.95 | AE2: 0.95 | AF2: 0.95
A3: 69 | B3: S1 | C3: 0.2159 | D3: 0.3448 | E3: 0.5047 | F3: 0.6851 | G3: 0.8599 | H3: 0.9397 | I3: 0.9494 | J3: 0.95 | K3: 0.95 | L3: 0.95 | M3: 0.95 | N3: 0.95 | O3: 0.95 | P3: 0.95 | Q3: 0.95 | R3: 0.95 | S3: 0.95 | T3: 0.95 | U3: 0.95 | V3: 0.95 | W3: 0.95 | X3: 0.95 | Y3: 0.95 | Z3: 0.95 | AA3: 0.95 | AB3: 0.95 | AC3: 0.95 | AD3: 0.95 | AE3: 0.95 | AF3: 0.95
A4: 196 | B4: S2 | C4: 0.098 | D4: 0.1587 | E4: 0.256 | F4: 0.3949 | G4: 0.5856 | H4: 0.7751 | I4: 0.8794 | J4: 0.9333 | K4: 0.9491 | L4: 0.95 | M4: 0.95 | N4: 0.95 | O4: 0.95 | P4: 0.95 | Q4: 0.95 | R4: 0.95 | S4: 0.95 | T4: 0.95 | U4: 0.95 | V4: 0.95 | W4: 0.95 | X4: 0.95 | Y4: 0.95 | Z4: 0.95 | AA4: 0.95 | AB4: 0.95 | AC4: 0.95 | AD4: 0.95 | AE4: 0.95 | AF4: 0.95
A5: 534 | B5: S3 | C5: 0.0639 | D5: 0.0844 | E5: 0.1243 | F5: 0.1981 | G5: 0.3287 | H5: 0.5005 | I5: 0.6397 | J5: 0.767 | K5: 0.8732 | L5: 0.9301 | M5: 0.9484 | N5: 0.95 | O5: 0.95 | P5: 0.95 | Q5: 0.95 | R5: 0.95 | S5: 0.95 | T5: 0.95 | U5: 0.95 | V5: 0.95 | W5: 0.95 | X5: 0.95 | Y5: 0.95 | Z5: 0.95 | AA5: 0.95 | AB5: 0.95 | AC5: 0.95 | AD5: 0.95 | AE5: 0.95 | AF5: 0.95
A6: 698 | B6: S4 | C6: 0.054 | D6: 0.0602 | E6: 0.0734 | F6: 0.1018 | G6: 0.1667 | H6: 0.284 | I6: 0.4072 | J6: 0.5484 | K6: 0.7052 | L6: 0.8333 | M6: 0.9171 | N6: 0.9465 | O6: 0.9499 | P6: 0.95 | Q6: 0.95 | R6: 0.95 | S6: 0.95 | T6: 0.95 | U6: 0.95 | V6: 0.95 | W6: 0.95 | X6: 0.95 | Y6: 0.95 | Z6: 0.95 | AA6: 0.95 | AB6: 0.95 | AC6: 0.95 | AD6: 0.95 | AE6: 0.95 | AF6: 0.95
A7: 1268 | B7: S5 | C7: 0.0518 | D7: 0.0547 | E7: 0.061 | F7: 0.0749 | G7: 0.1085 | H7: 0.1761 | I7: 0.2579 | J7: 0.3668 | K7: 0.5118 | L7: 0.6564 | M7: 0.7871 | N7: 0.8826 | O7: 0.9313 | P7: 0.9479 | Q7: 0.9499 | R7: 0.95 | S7: 0.95 | T7: 0.95 | U7: 0.95 | V7: 0.95 | W7: 0.95 | X7: 0.95 | Y7: 0.95 | Z7: 0.95 | AA7: 0.95 | AB7: 0.95 | AC7: 0.95 | AD7: 0.95 | AE7: 0.95 | AF7: 0.95
A8: 2021 | B8: S6 | C8: 0.0504 | D8: 0.0511 | E8: 0.0526 | F8: 0.0562 | G8: 0.0658 | H8: 0.0889 | I8: 0.123 | J8: 0.1806 | K8: 0.2832 | L8: 0.4197 | M8: 0.5693 | N8: 0.7008 | O8: 0.8035 | P8: 0.8837 | Q8: 0.9249 | R8: 0.9442 | S8: 0.9493 | T8: 0.95 | U8: 0.95 | V8: 0.95 | W8: 0.95 | X8: 0.95 | Y8: 0.95 | Z8: 0.95 | AA8: 0.95 | AB8: 0.95 | AC8: 0.95 | AD8: 0.95 | AE8: 0.95 | AF8: 0.95
A9: 2806 | B9: S7 | C9: 0.0501 | D9: 0.0503 | E9: 0.0508 | F9: 0.052 | G9: 0.0551 | H9: 0.0632 | I9: 0.0765 | J9: 0.102 | K9: 0.1563 | L9: 0.2499 | M9: 0.391 | N9: 0.5405 | O9: 0.6589 | P9: 0.7599 | Q9: 0.8303 | R9: 0.8885 | S9: 0.9257 | T9: 0.9442 | U9: 0.9492 | V9: 0.95 | W9: 0.95 | X9: 0.95 | Y9: 0.95 | Z9: 0.95 | AA9: 0.95 | AB9: 0.95 | AC9: 0.95 | AD9: 0.95 | AE9: 0.95 | AF9: 0.95
A10: 3785 | B10: S8 | C10: 0.0501 | D10: 0.0502 | E10: 0.0504 | F10: 0.0509 | G10: 0.0524 | H10: 0.0562 | I10: 0.0625 | J10: 0.0751 | K10: 0.1046 | L10: 0.1634 | M10: 0.2735 | N10: 0.4224 | O10: 0.5535 | P10: 0.6643 | Q10: 0.7412 | R10: 0.8082 | S10: 0.8615 | T10: 0.9045 | U10: 0.9307 | V10: 0.9445 | W10: 0.9489 | X10: 0.9499 | Y10: 0.95 | Z10: 0.95 | AA10: 0.95 | AB10: 0.95 | AC10: 0.95 | AD10: 0.95 | AE10: 0.95 | AF10: 0.95
A11: 4374 | B11: S9 | C11: 0.05 | D11: 0.0501 | E11: 0.0502 | F11: 0.0504 | G11: 0.0512 | H11: 0.0531 | I11: 0.0564 | J11: 0.0631 | K11: 0.0791 | L11: 0.1131 | M11: 0.1851 | N11: 0.3049 | O11: 0.436 | P11: 0.5548 | Q11: 0.6352 | R11: 0.7044 | S11: 0.7614 | T11: 0.8141 | U11: 0.8577 | V11: 0.8962 | W11: 0.9224 | X11: 0.9392 | Y11: 0.9466 | Z11: 0.9493 | AA11: 0.9499 | AB11: 0.95 | AC11: 0.95 | AD11: 0.95 | AE11: 0.95 | AF11: 0.95
A12: 4503 | B12: S10 | C12: 0.05 | D12: 0.05 | E12: 0.0501 | F12: 0.0502 | G12: 0.0506 | H12: 0.0516 | I12: 0.0533 | J12: 0.0568 | K12: 0.0652 | L12: 0.0837 | M12: 0.1258 | N12: 0.2072 | O12: 0.319 | P12: 0.4423 | Q12: 0.5311 | R12: 0.6075 | S12: 0.6688 | T12: 0.7233 | U12: 0.7684 | V12: 0.8122 | W12: 0.8497 | X12: 0.8849 | Y12: 0.9119 | Z12: 0.9318 | AA12: 0.943 | AB12: 0.9481 | AC12: 0.9497 | AD12: 0.95 | AE12: 0.95 | AF12: 0.95
A13: 4470 | B13: S11 | C13: 0.05 | D13: 0.05 | E13: 0.05 | F13: 0.0501 | G13: 0.0503 | H13: 0.0508 | I13: 0.0517 | J13: 0.0535 | K13: 0.058 | L13: 0.0678 | M13: 0.0913 | N13: 0.141 | O13: 0.2217 | P13: 0.3333 | Q13: 0.4278 | R13: 0.5118 | S13: 0.5783 | T13: 0.6357 | U13: 0.6814 | V13: 0.725 | W13: 0.7635 | X13: 0.8033 | Y13: 0.8395 | Z13: 0.8747 | AA13: 0.9039 | AB13: 0.9266 | AC13: 0.9407 | AD13: 0.9474 | AE13: 0.95 | AF13: 0.95
... A31: 2137 | B31: L15 | C31: 0.05 | D31: 0.05 | E31: 0.0501 | F31: 0.0502 | G31: 0.0506 | H31: 0.0517 | I31: 0.0534 | J31: 0.057 | K31: 0.0659 | L31: 0.0858 | M31: 0.1328 | N31: 0.2331 | O31: 0.3961 | P31: 0.6173 | Q31: 0.7855 | R31: 0.895 | S31: 0.9388 | T31: 0.9491 | U31: 0.95 | V31: 0.95 | W31: 0.95 | X31: 0.95 | Y31: 0.95 | Z31: 0.95 | AA31: 0.95 | AB31: 0.95 | AC31: 0.95 | AD31: 0.95 | AE31: 0.95 | AF31: 0.95

Sheet Quiz 1
A1: Quiz 1 – Scope, Weights, Thresholds, Pass Probabilities
A3: Controls (blue = editable) | D3: Threshold & pass probabilities
A4: Quiz level (n) | B4: 1 | D4: Pass threshold (expected correct at ability n) | E4: =M21 -> 14.128622
A5: Total questions (N) | B5: 31 | D5: Pass threshold (rounded up) | E5: =ROUNDUP($E$4,0) -> 15
A6: Note: Weight share is proportional to (items × weight).
A7: Ability n-1 | B7: =IF(OR($B$4-1<0.5,$B$4-1>15),"",$B$4-1) | D7: P-1 (ability n-1) | E7: =IF($B$7="",-1,IF(K24=0,IF(K21>=$E$5,1,0),1-_xludf.NORM.DIST($E$5-0.5,K21,K24,TRUE))) -> -1
A8: Ability n-0.5 | B8: =IF(OR($B$4-0.5<0.5,$B$4-0.5>15),"",$B$4-0.5) -> 0.5 | D8: P-0.5 (ability n-0.5) | E8: =IF($B$8="",-1,IF(L24=0,IF(L21>=$E$5,1,0),1-_xlfn.NORM.DIST($E$5-0.5,L21,L24,TRUE))) -> 0.015030182
A9: Ability n | B9: =$B$4 -> 1 | D9: P-0 (ability n) | E9: =IF($B$9="",-1,IF(M24=0,IF(M21>=$E$5,1,0),1-_xlfn.NORM.DIST($E$5-0.5,M21,M24,TRUE))) -> 0.44353548
A10: Ability n+0.5 | B10: =IF(OR($B$4+0.5<0.5,$B$4+0.5>15),"",$B$4+0.5) -> 1.5 | D10: P+0.5 (ability n+0.5) | E10: =IF($B$10="",-1,IF(N24=0,IF(N21>=$E$5,1,0),1-_xlfn.NORM.DIST($E$5-0.5,N21,N24,TRUE))) -> 0.96383445
E11: n-1 | F11: n-0.5 | G11: n | H11: n+0.5
D12: Mean correct | E12: =IF($B$7="","",K21) | F12: =IF($B$8="","",L21) -> 9.178852 | G12: =IF($B$9="","",M21) -> 14.128622 | H12: =IF($B$10="","",N21) -> 19.078051
D13: Accuracy % | E13: =IF($B$7="","",K21/$B$5) | F13: =IF($B$8="","",L21/$B$5) -> 0.296092 | G13: =IF($B$9="","",M21/$B$5) -> 0.455762 | H13: =IF($B$10="","",N21/$B$5) -> 0.615421
D14: Std dev correct | E14: =IF($B$7="","",K24) | F14: =IF($B$8="","",L24) -> 2.4529399 | G14: =IF($B$9="","",M24) -> 2.6151272 | H14: =IF($B$10="","",N24) -> 2.5475672
A17: Set | B17: Items | C17: Weight (per item) | D17: Items×Weight | E17: Weight share | F17: Expected questions | G17: p(correct) @ n-1 | H17: p(correct) @ n-0.5 | I17: p(correct) @ n | J17: p(correct) @ n+0.5 | K17: Exp correct @ n-1 | L17: Exp correct @ n-0.5 | M17: Exp correct @ n | N17: Exp correct @ n+0.5
A18: S0 | B18: =INDEX(AccuracyTable!$A$2:$A$31, MATCH($A18, AccuracyTable!$B$2:$B$31, 0)) -> 15 | C18: 1 | D18: =B18*C18 -> 15 | E18: =D18/SUM($D$18:$D$20) -> 0.15 | F18: =$B$5*E18 -> 4.65 | G18: =IF($B$7="","",INDEX(AccuracyTable!$C$2:$AF$31, MATCH($A18, AccuracyTable!$B$2:$B$31, 0), MATCH($B$7, AccuracyTable!$C$1:$AF$1, 0))) | H18: =IF($B$8="","",INDEX(AccuracyTable!$C$2:$AF$31, MATCH($A18, AccuracyTable!$B$2:$B$31, 0), MATCH($B$8, AccuracyTable!$C$1:$AF$1, 0))) -> 0.4815 | I18: =IF($B$9="","",INDEX(AccuracyTable!$C$2:$AF$31, MATCH($A18, AccuracyTable!$B$2:$B$31, 0), MATCH($B$9, AccuracyTable!$C$1:$AF$1, 0))) -> 0.7126 | J18: =IF($B$10="","",INDEX(AccuracyTable!$C$2:$AF$31, MATCH($A18, AccuracyTable!$B$2:$B$31, 0), MATCH($B$10, AccuracyTable!$C$1:$AF$1, 0))) -> 0.8726 | K18: =IF($B$7="","",F18*G18) | L18: =IF($B$8="","",F18*H18) -> 2.238975 | M18: =IF($B$9="","",F18*I18) -> 3.31359 | N18: =IF($B$10="","",F18*J18) -> 4.05759
A19: S1 | B19: =INDEX(AccuracyTable!$A$2:$A$31, MATCH($A19, AccuracyTable!$B$2:$B$31, 0)) -> 69 | C19: 1 | D19: =B19*C19 -> 69 | E19: =D19/SUM($D$18:$D$20) -> 0.69 | F19: =$B$5*E19 -> 21.39 | G19: =IF($B$7="","",INDEX(AccuracyTable!$C$2:$AF$31, MATCH($A19, AccuracyTable!$B$2:$B$31, 0), MATCH($B$7, AccuracyTable!$C$1:$AF$1, 0))) | H19: =IF($B$8="","",INDEX(AccuracyTable!$C$2:$AF$31, MATCH($A19, AccuracyTable!$B$2:$B$31, 0), MATCH($B$8, AccuracyTable!$C$1:$AF$1, 0))) -> 0.2159 | I19: =IF($B$9="","",INDEX(AccuracyTable!$C$2:$AF$31, MATCH($A19, AccuracyTable!$B$2:$B$31, 0), MATCH($B$9, AccuracyTable!$C$1:$AF$1, 0))) -> 0.3448 | J19: =IF($B$10="","",INDEX(AccuracyTable!$C$2:$AF$31, MATCH($A19, AccuracyTable!$B$2:$B$31, 0), MATCH($B$10, AccuracyTable!$C$1:$AF$1, 0))) -> 0.5047 | K19: =IF($B$7="","",F19*G19) | L19: =IF($B$8="","",F19*H19) -> 4.618101 | M19: =IF($B$9="","",F19*I19) -> 7.375272 | N19: =IF($B$10="","",F19*J19) -> 10.795533
A20: L2 | B20: =INDEX(AccuracyTable!$A$2:$A$31, MATCH($A20, AccuracyTable!$B$2:$B$31, 0)) -> 16 | C20: 1 | D20: =B20*C20 -> 16 | E20: =D20/SUM($D$18:$D$20) -> 0.16 | F20: =$B$5*E20 -> 4.96 | G20: =IF($B$7="","",INDEX(AccuracyTable!$C$2:$AF$31, MATCH($A20, AccuracyTable!$B$2:$B$31, 0), MATCH($B$7, AccuracyTable!$C$1:$AF$1, 0))) | H20: =IF($B$8="","",INDEX(AccuracyTable!$C$2:$AF$31, MATCH($A20, AccuracyTable!$B$2:$B$31, 0), MATCH($B$8, AccuracyTable!$C$1:$AF$1, 0))) -> 0.4681 | I20: =IF($B$9="","",INDEX(AccuracyTable!$C$2:$AF$31, MATCH($A20, AccuracyTable!$B$2:$B$31, 0), MATCH($B$9, AccuracyTable!$C$1:$AF$1, 0))) -> 0.6935 | J20: =IF($B$10="","",INDEX(AccuracyTable!$C$2:$AF$31, MATCH($A20, AccuracyTable!$B$2:$B$31, 0), MATCH($B$10, AccuracyTable!$C$1:$AF$1, 0))) -> 0.8518 | K20: =IF($B$7="","",F20*G20) | L20: =IF($B$8="","",F20*H20) -> 2.321776 | M20: =IF($B$9="","",F20*I20) -> 3.43976 | N20: =IF($B$10="","",F20*J20) -> 4.224928
A21: TOTAL | D21: =SUM($D$18:$D$20) -> 100 | E21: =SUM($E$18:$E$20) -> 1 | F21: =SUM($F$18:$F$20) -> 31 | K21: =SUM($K$18:$K$20) -> 0 | L21: =SUM($L$18:$L$20) -> 9.178852 | M21: =SUM($M$18:$M$20) -> 14.128622 | N21: =SUM($N$18:$N$20) -> 19.078051
A23: Variance (approx) | K23: =IF($B$7="","",SUMPRODUCT($F$18:$F$20,$G$18:$G$20,(1-$G$18:$G$20))) | L23: =IF($B$8="","",SUMPRODUCT($F$18:$F$20,$H$18:$H$20,(1-$H$18:$H$20))) -> 6.0169142 | M23: =IF($B$9="","",SUMPRODUCT($F$18:$F$20,$I$18:$I$20,(1-$I$18:$I$20))) -> 6.8388904 | N23: =IF($B$10="","",SUMPRODUCT($F$18:$F$20,$J$18:$J$20,(1-$J$18:$J$20))) -> 6.4900988
A24: Std dev (approx) | K24: =IF($B$7="","",SQRT(K23)) | L24: =IF($B$8="","",SQRT(L23)) -> 2.4529399 | M24: =IF($B$9="","",SQRT(M23)) -> 2.6151272 | N24: =IF($B$10="","",SQRT(N23)) -> 2.5475672

Sheet Quiz 2
A1: Quiz 2 – Scope, Weights, Thresholds, Pass Probabilities
A3: Controls (blue = editable) | D3: Threshold & pass probabilities
A4: Quiz level (n) | B4: 2 | D4: Pass threshold (expected correct at ability n) | E4: =M25 -> 39.409155 | F4: =$M$25 -> 39.409155
A5: Total questions (N) | B5: 91 | D5: Pass threshold (rounded up) | E5: =ROUNDUP($E$4,0) -> 40
A6: Note: Weight share is proportional to (items × weight).
A7: Ability n-1 | B7: =IF(OR($B$4-1<0.5,$B$4-1>15),"",$B$4-1) -> 1 | D7: P-1 (ability n-1) | E7: =IF($B$7="",-1,IF(K28=0,IF(K25>=$E$5,1,0),1-_xlfn.NORM.DIST($E$5-0.5,K25,K28,TRUE))) -> 3.0544298e-09
A8: Ability n-0.5 | B8: =IF(OR($B$4-0.5<0.5,$B$4-0.5>15),"",$B$4-0.5) -> 1.5 | D8: P-0.5 (ability n-0.5) | E8: =IF($B$8="",-1,IF(L28=0,IF(L25>=$E$5,1,0),1-_xlfn.NORM.DIST($E$5-0.5,L25,L28,TRUE))) -> 0.0016165736
A9: Ability n | B9: =$B$4 -> 2 | D9: P-0 (ability n) | E9: =IF($B$9="",-1,IF(M28=0,IF(M25>=$E$5,1,0),1-_xlfn.NORM.DIST($E$5-0.5,M25,M28,TRUE))) -> 0.49162052
A10: Ability n+0.5 | B10: =IF(OR($B$4+0.5<0.5,$B$4+0.5>15),"",$B$4+0.5) -> 2.5 | D10: P+0.5 (ability n+0.5) | E10: =IF($B$10="",-1,IF(N28=0,IF(N25>=$E$5,1,0),1-_xlfn.NORM.DIST($E$5-0.5,N25,N28,TRUE))) -> 0.99981401
E11: n-1 | F11: n-0.5 | G11: n | H11: n+0.5
D12: Mean correct | E12: =IF($B$7="","",K25) -> 18.716442 | F12: =IF($B$8="","",L25) -> 27.687175 | G12: =IF($B$9="","",M25) -> 39.409155 | H12: =IF($B$10="","",N25) -> 54.809234
D13: Accuracy % | E13: =IF($B$7="","",K25/$B$5) -> 0.20567519 | F13: =IF($B$8="","",L25/$B$5) -> 0.30425467 | G13: =IF($B$9="","",M25/$B$5) -> 0.43306764 | H13: =IF($B$10="","",N25/$B$5) -> 0.60229928
D14: Std dev correct | E14: =IF($B$7="","",K28) -> 3.574897 | F14: =IF($B$8="","",L28) -> 4.0116158 | G14: =IF($B$9="","",M28) -> 4.3247468 | H14: =IF($B$10="","",N28) -> 4.3013103
A17: Set | B17: Items | C17: Weight (per item) | D17: Items×Weight | E17: Weight share | F17: Expected questions | G17: p(correct) @ n-1 | H17: p(correct) @ n-0.5 | I17: p(correct) @ n | J17: p(correct) @ n+0.5 | K17: Exp correct @ n-1 | L17: Exp correct @ n-0.5 | M17: Exp correct @ n | N17: Exp correct @ n+0.5
A18: S0 | B18: =INDEX(AccuracyTable!$A$2:$A$31, MATCH($A18, AccuracyTable!$B$2:$B$31, 0)) -> 15 | C18: 1 | D18: =B18*C18 -> 15 | E18: =D18/SUM($D$18:$D$24) -> 0.0284522 | F18: =$B$5*E18 -> 2.5891502 | G18: =IF($B$7="","",INDEX(AccuracyTable!$C$2:$AF$31, MATCH($A18, AccuracyTable!$B$2:$B$31, 0), MATCH($B$7, AccuracyTable!$C$1:$AF$1, 0))) -> 0.7126 | H18: =IF($B$8="","",INDEX(AccuracyTable!$C$2:$AF$31, MATCH($A18, AccuracyTable!$B$2:$B$31, 0), MATCH($B$8, AccuracyTable!$C$1:$AF$1, 0))) -> 0.8726 | I18: =IF($B$9="","",INDEX(AccuracyTable!$C$2:$AF$31, MATCH($A18, AccuracyTable!$B$2:$B$31, 0), MATCH($B$9, AccuracyTable!$C$1:$AF$1, 0))) -> 0.9394 | J18: =IF($B$10="","",INDEX(AccuracyTable!$C$2:$AF$31, MATCH($A18, AccuracyTable!$B$2:$B$31, 0), MATCH($B$10, AccuracyTable!$C$1:$AF$1, 0))) -> 0.9498 | K18: =IF($B$7="","",F18*G18) -> 1.8450285 | L18: =IF($B$8="","",F18*H18) -> 2.2592925 | M18: =IF($B$9="","",F18*I18) -> 2.4322477 | N18: =IF($B$10="","",F18*J18) -> 2.4591749
A19: S1 | B19: =INDEX(AccuracyTable!$A$2:$A$31, MATCH($A19, AccuracyTable!$B$2:$B$31, 0)) -> 69 | C19: 1.4 | D19: =B19*C19 -> 96.6 | E19: =D19/SUM($D$18:$D$24) -> 0.18323217 | F19: =$B$5*E19 -> 16.674127 | G19: =IF($B$7="","",INDEX(AccuracyTable!$C$2:$AF$31, MATCH($A19, AccuracyTable!$B$2:$B$31, 0), MATCH($B$7, AccuracyTable!$C$1:$AF$1, 0))) -> 0.3448 | H19: =IF($B$8="","",INDEX(AccuracyTable!$C$2:$AF$31, MATCH($A19, AccuracyTable!$B$2:$B$31, 0), MATCH($B$8, AccuracyTable!$C$1:$AF$1, 0))) -> 0.5047 | I19: =IF($B$9="","",INDEX(AccuracyTable!$C$2:$AF$31, MATCH($A19, AccuracyTable!$B$2:$B$31, 0), MATCH($B$9, AccuracyTable!$C$1:$AF$1, 0))) -> 0.6851 | J19: =IF($B$10="","",INDEX(AccuracyTable!$C$2:$AF$31, MATCH($A19, AccuracyTable!$B$2:$B$31, 0), MATCH($B$10, AccuracyTable!$C$1:$AF$1, 0))) -> 0.8599 | K19: =IF($B$7="","",F19*G19) -> 5.7492392 | L19: =IF($B$8="","",F19*H19) -> 8.4154321 | M19: =IF($B$9="","",F19*I19) -> 11.423445 | N19: =IF($B$10="","",F19*J19) -> 14.338082
A20: S2 | B20: =INDEX(AccuracyTable!$A$2:$A$31, MATCH($A20, AccuracyTable!$B$2:$B$31, 0)) -> 196 | C20: 1.3 | D20: =B20*C20 -> 254.8 | E20: =D20/SUM($D$18:$D$24) -> 0.48330804 | F20: =$B$5*E20 -> 43.981032 | G20: =IF($B$7="","",INDEX(AccuracyTable!$C$2:$AF$31, MATCH($A20, AccuracyTable!$B$2:$B$31, 0), MATCH($B$7, AccuracyTable!$C$1:$AF$1, 0))) -> 0.1587 | H20: =IF($B$8="","",INDEX(AccuracyTable!$C$2:$AF$31, MATCH($A20, AccuracyTable!$B$2:$B$31, 0), MATCH($B$8, AccuracyTable!$C$1:$AF$1, 0))) -> 0.256 | I20: =IF($B$9="","",INDEX(AccuracyTable!$C$2:$AF$31, MATCH($A20, AccuracyTable!$B$2:$B$31, 0), MATCH($B$9, AccuracyTable!$C$1:$AF$1, 0))) -> 0.3949 | J20: =IF($B$10="","",INDEX(AccuracyTable!$C$2:$AF$31, MATCH($A20, AccuracyTable!$B$2:$B$31, 0), MATCH($B$10, AccuracyTable!$C$1:$AF$1, 0))) -> 0.5856 | K20: =IF($B$7="","",F20*G20) -> 6.9797898 | L20: =IF($B$8="","",F20*H20) -> 11.259144 | M20: =IF($B$9="","",F20*I20) -> 17.368109 | N20: =IF($B$10="","",F20*J20) -> 25.755292
A21: S3 | B21: =INDEX(AccuracyTable!$A$2:$A$31, MATCH($A21, AccuracyTable!$B$2:$B$31, 0)) -> 534 | C21: 0.2 | D21: =B21*C21 -> 106.8 | E21: =D21/SUM($D$18:$D$24) -> 0.20257967 | F21: =$B$5*E21 -> 18.43475 | G21: =IF($B$7="","",INDEX(AccuracyTable!$C$2:$AF$31, MATCH($A21, AccuracyTable!$B$2:$B$31, 0), MATCH($B$7, AccuracyTable!$C$1:$AF$1, 0))) -> 0.0844 | H21: =IF($B$8="","",INDEX(AccuracyTable!$C$2:$AF$31, MATCH($A21, AccuracyTable!$B$2:$B$31, 0), MATCH($B$8, AccuracyTable!$C$1:$AF$1, 0))) -> 0.1243 | I21: =IF($B$9="","",INDEX(AccuracyTable!$C$2:$AF$31, MATCH($A21, AccuracyTable!$B$2:$B$31, 0), MATCH($B$9, AccuracyTable!$C$1:$AF$1, 0))) -> 0.1981 | J21: =IF($B$10="","",INDEX(AccuracyTable!$C$2:$AF$31, MATCH($A21, AccuracyTable!$B$2:$B$31, 0), MATCH($B$10, AccuracyTable!$C$1:$AF$1, 0))) -> 0.3287 | K21: =IF($B$7="","",F21*G21) -> 1.5558929 | L21: =IF($B$8="","",F21*H21) -> 2.2914394 | M21: =IF($B$9="","",F21*I21) -> 3.6519239 | N21: =IF($B$10="","",F21*J21) -> 6.0595022
A22: L2 | B22: =INDEX(AccuracyTable!$A$2:$A$31, MATCH($A22, AccuracyTable!$B$2:$B$31, 0)) -> 16 | C22: 1 | D22: =B22*C22 -> 16 | E22: =D22/SUM($D$18:$D$24) -> 0.030349014 | F22: =$B$5*E22 -> 2.7617602 | G22: =IF($B$7="","",INDEX(AccuracyTable!$C$2:$AF$31, MATCH($A22, AccuracyTable!$B$2:$B$31, 0), MATCH($B$7, AccuracyTable!$C$1:$AF$1, 0))) -> 0.6935 | H22: =IF($B$8="","",INDEX(AccuracyTable!$C$2:$AF$31, MATCH($A22, AccuracyTable!$B$2:$B$31, 0), MATCH($B$8, AccuracyTable!$C$1:$AF$1, 0))) -> 0.8518 | I22: =IF($B$9="","",INDEX(AccuracyTable!$C$2:$AF$31, MATCH($A22, AccuracyTable!$B$2:$B$31, 0), MATCH($B$9, AccuracyTable!$C$1:$AF$1, 0))) -> 0.9221 | J22: =IF($B$10="","",INDEX(AccuracyTable!$C$2:$AF$31, MATCH($A22, AccuracyTable!$B$2:$B$31, 0), MATCH($B$10, AccuracyTable!$C$1:$AF$1, 0))) -> 0.946 | K22: =IF($B$7="","",F22*G22) -> 1.9152807 | L22: =IF($B$8="","",F22*H22) -> 2.3524674 | M22: =IF($B$9="","",F22*I22) -> 2.5466191 | N22: =IF($B$10="","",F22*J22) -> 2.6126252
A23: L3 | B23: =INDEX(AccuracyTable!$A$2:$A$31, MATCH($A23, AccuracyTable!$B$2:$B$31, 0)) -> 36 | C23: 0.5 | D23: =B23*C23 -> 18 | E23: =D23/SUM($D$18:$D$24) -> 0.03414264 | F23: =$B$5*E23 -> 3.1069803 | G23: =IF($B$7="","",INDEX(AccuracyTable!$C$2:$AF$31, MATCH($A23, AccuracyTable!$B$2:$B$31, 0), MATCH($B$7, AccuracyTable!$C$1:$AF$1, 0))) -> 0.1267 | H23: =IF($B$8="","",INDEX(AccuracyTable!$C$2:$AF$31, MATCH($A23, AccuracyTable!$B$2:$B$31, 0), MATCH($B$8, AccuracyTable!$C$1:$AF$1, 0))) -> 0.2224 | I23: =IF($B$9="","",INDEX(AccuracyTable!$C$2:$AF$31, MATCH($A23, AccuracyTable!$B$2:$B$31, 0), MATCH($B$9, AccuracyTable!$C$1:$AF$1, 0))) -> 0.4058 | J23: =IF($B$10="","",INDEX(AccuracyTable!$C$2:$AF$31, MATCH($A23, AccuracyTable!$B$2:$B$31, 0), MATCH($B$10, AccuracyTable!$C$1:$AF$1, 0))) -> 0.6996 | K23: =IF($B$7="","",F23*G23) -> 0.3936544 | L23: =IF($B$8="","",F23*H23) -> 0.69099241 | M23: =IF($B$9="","",F23*I23) -> 1.2608126 | N23: =IF($B$10="","",F23*J23) -> 2.1736434
A24: L4 | B24: =INDEX(AccuracyTable!$A$2:$A$31, MATCH($A24, AccuracyTable!$B$2:$B$31, 0)) -> 100 | C24: 0.2 | D24: =B24*C24 -> 20 | E24: =D24/SUM($D$18:$D$24) -> 0.037936267 | F24: =$B$5*E24 -> 3.4522003 | G24: =IF($B$7="","",INDEX(AccuracyTable!$C$2:$AF$31, MATCH($A24, AccuracyTable!$B$2:$B$31, 0), MATCH($B$7, AccuracyTable!$C$1:$AF$1, 0))) -> 0.0804 | H24: =IF($B$8="","",INDEX(AccuracyTable!$C$2:$AF$31, MATCH($A24, AccuracyTable!$B$2:$B$31, 0), MATCH($B$8, AccuracyTable!$C$1:$AF$1, 0))) -> 0.1212 | I24: =IF($B$9="","",INDEX(AccuracyTable!$C$2:$AF$31, MATCH($A24, AccuracyTable!$B$2:$B$31, 0), MATCH($B$9, AccuracyTable!$C$1:$AF$1, 0))) -> 0.2103 | J24: =IF($B$10="","",INDEX(AccuracyTable!$C$2:$AF$31, MATCH($A24, AccuracyTable!$B$2:$B$31, 0), MATCH($B$10, AccuracyTable!$C$1:$AF$1, 0))) -> 0.4087 | K24: =IF($B$7="","",F24*G24) -> 0.2775569 | L24: =IF($B$8="","",F24*H24) -> 0.41840668 | M24: =IF($B$9="","",F24*I24) -> 0.72599772 | N24: =IF($B$10="","",F24*J24) -> 1.4109143
A25: TOTAL | D25: =SUM($D$18:$D$24) -> 527.2 | E25: =SUM($E$18:$E$24) -> 1 | F25: =SUM($F$18:$F$24) -> 91 | K25: =SUM($K$18:$K$24) -> 18.716442 | L25: =SUM($L$18:$L$24) -> 27.687175 | M25: =SUM($M$18:$M$24) -> 39.409155 | N25: =SUM($N$18:$N$24) -> 54.809234
A27: Variance (approx) | K27: =IF($B$7="","",SUMPRODUCT($F$18:$F$24,$G$18:$G$24,(1-$G$18:$G$24))) -> 12.779889 | L27: =IF($B$8="","",SUMPRODUCT($F$18:$F$24,$H$18:$H$24,(1-$H$18:$H$24))) -> 16.093061 | M27: =IF($B$9="","",SUMPRODUCT($F$18:$F$24,$I$18:$I$24,(1-$I$18:$I$24))) -> 18.703435 | N27: =IF($B$10="","",SUMPRODUCT($F$18:$F$24,$J$18:$J$24,(1-$J$18:$J$24))) -> 18.501271
A28: Std dev (approx) | K28: =IF($B$7="","",SQRT(K27)) -> 3.574897 | L28: =IF($B$8="","",SQRT(L27)) -> 4.0116158 | M28: =IF($B$9="","",SQRT(M27)) -> 4.3247468 | N28: =IF($B$10="","",SQRT(N27)) -> 4.3013103

Sheet Quiz 3
A1: Quiz 3 – Scope, Weights, Thresholds, Pass Probabilities
A3: Controls (blue = editable) | D3: Threshold & pass probabilities
A4: Quiz level (n) | B4: 3 | D4: Pass threshold (expected correct at ability n) | E4: =M25 -> 39.221046
A5: Total questions (N) | B5: 73 | D5: Pass threshold (rounded up) | E5: =ROUNDUP($E$4,0) -> 40
A6: Note: Weight share is proportional to (items × weight).
A7: Ability n-1 | B7: =IF(OR($B$4-1<0.5,$B$4-1>15),"",$B$4-1) -> 2 | D7: P-1 (ability n-1) | E7: =IF($B$7="",-1,IF(K28=0,IF(K25>=$E$5,1,0),1-_xlfn.NORM.DIST($E$5-0.5,K25,K28,TRUE))) -> 1.3916979e-11
A8: Ability n-0.5 | B8: =IF(OR($B$4-0.5<0.5,$B$4-0.5>15),"",$B$4-0.5) -> 2.5 | D8: P-0.5 (ability n-0.5) | E8: =IF($B$8="",-1,IF(L28=0,IF(L25>=$E$5,1,0),1-_xlfn.NORM.DIST($E$5-0.5,L25,L28,TRUE))) -> 0.00040150665
A9: Ability n | B9: =$B$4 -> 3 | D9: P-0 (ability n) | E9: =IF($B$9="",-1,IF(M28=0,IF(M25>=$E$5,1,0),1-_xlfn.NORM.DIST($E$5-0.5,M25,M28,TRUE))) -> 0.47182439
A10: Ability n+0.5 | B10: =IF(OR($B$4+0.5<0.5,$B$4+0.5>15),"",$B$4+0.5) -> 3.5 | D10: P+0.5 (ability n+0.5) | E10: =IF($B$10="",-1,IF(N28=0,IF(N25>=$E$5,1,0),1-_xlfn.NORM.DIST($E$5-0.5,N25,N28,TRUE))) -> 0.99375744
E11: n-1 | F11: n-0.5 | G11: n | H11: n+0.5
D12: Mean correct | E12: =IF($B$7="","",K25) -> 16.831403 | F12: =IF($B$8="","",L25) -> 26.666899 | G12: =IF($B$9="","",M25) -> 39.221046 | H12: =IF($B$10="","",N25) -> 48.852111
D13: Accuracy % | E13: =IF($B$7="","",K25/$B$5) -> 0.23056716 | F13: =IF($B$8="","",L25/$B$5) -> 0.36529999 | G13: =IF($B$9="","",M25/$B$5) -> 0.5372746 | H13: =IF($B$10="","",N25/$B$5) -> 0.669207
D14: Std dev correct | E14: =IF($B$7="","",K28) -> 3.4049215 | F14: =IF($B$8="","",L28) -> 3.8287717 | G14: =IF($B$9="","",M28) -> 3.9464634 | H14: =IF($B$10="","",N28) -> 3.7436483
A17: Set | B17: Items | C17: Weight (per item) | D17: Items×Weight | E17: Weight share | F17: Expected questions | G17: p(correct) @ n-1 | H17: p(correct) @ n-0.5 | I17: p(correct) @ n | J17: p(correct) @ n+0.5 | K17: Exp correct @ n-1 | L17: Exp correct @ n-0.5 | M17: Exp correct @ n | N17: Exp correct @ n+0.5
A18: S1 | B18: =INDEX(AccuracyTable!$A$2:$A$31, MATCH($A18, AccuracyTable!$B$2:$B$31, 0)) -> 69 | C18: 1 | D18: =B18*C18 -> 69 | E18: =D18/SUM($D$18:$D$24) -> 0.040607345 | F18: =$B$5*E18 -> 2.9643362 | G18: =IF($B$7="","",INDEX(AccuracyTable!$C$2:$AF$31, MATCH($A18, AccuracyTable!$B$2:$B$31, 0), MATCH($B$7, AccuracyTable!$C$1:$AF$1, 0))) -> 0.6851 | H18: =IF($B$8="","",INDEX(AccuracyTable!$C$2:$AF$31, MATCH($A18, AccuracyTable!$B$2:$B$31, 0), MATCH($B$8, AccuracyTable!$C$1:$AF$1, 0))) -> 0.8599 | I18: =IF($B$9="","",INDEX(AccuracyTable!$C$2:$AF$31, MATCH($A18, AccuracyTable!$B$2:$B$31, 0), MATCH($B$9, AccuracyTable!$C$1:$AF$1, 0))) -> 0.9397 | J18: =IF($B$10="","",INDEX(AccuracyTable!$C$2:$AF$31, MATCH($A18, AccuracyTable!$B$2:$B$31, 0), MATCH($B$10, AccuracyTable!$C$1:$AF$1, 0))) -> 0.9494 | K18: =IF($B$7="","",F18*G18) -> 2.0308667 | L18: =IF($B$8="","",F18*H18) -> 2.5490327 | M18: =IF($B$9="","",F18*I18) -> 2.7855867 | N18: =IF($B$10="","",F18*J18) -> 2.8143407
A19: S2 | B19: =INDEX(AccuracyTable!$A$2:$A$31, MATCH($A19, AccuracyTable!$B$2:$B$31, 0)) -> 196 | C19: 1.5 | D19: =B19*C19 -> 294 | E19: =D19/SUM($D$18:$D$24) -> 0.1730226 | F19: =$B$5*E19 -> 12.63065 | G19: =IF($B$7="","",INDEX(AccuracyTable!$C$2:$AF$31, MATCH($A19, AccuracyTable!$B$2:$B$31, 0), MATCH($B$7, AccuracyTable!$C$1:$AF$1, 0))) -> 0.3949 | H19: =IF($B$8="","",INDEX(AccuracyTable!$C$2:$AF$31, MATCH($A19, AccuracyTable!$B$2:$B$31, 0), MATCH($B$8, AccuracyTable!$C$1:$AF$1, 0))) -> 0.5856 | I19: =IF($B$9="","",INDEX(AccuracyTable!$C$2:$AF$31, MATCH($A19, AccuracyTable!$B$2:$B$31, 0), MATCH($B$9, AccuracyTable!$C$1:$AF$1, 0))) -> 0.7751 | J19: =IF($B$10="","",INDEX(AccuracyTable!$C$2:$AF$31, MATCH($A19, AccuracyTable!$B$2:$B$31, 0), MATCH($B$10, AccuracyTable!$C$1:$AF$1, 0))) -> 0.8794 | K19: =IF($B$7="","",F19*G19) -> 4.9878436 | L19: =IF($B$8="","",F19*H19) -> 7.3965085 | M19: =IF($B$9="","",F19*I19) -> 9.7900166 | N19: =IF($B$10="","",F19*J19) -> 11.107393
A20: S3 | B20: =INDEX(AccuracyTable!$A$2:$A$31, MATCH($A20, AccuracyTable!$B$2:$B$31, 0)) -> 534 | C20: 1.3 | D20: =B20*C20 -> 694.2 | E20: =D20/SUM($D$18:$D$24) -> 0.4085452 | F20: =$B$5*E20 -> 29.823799 | G20: =IF($B$7="","",INDEX(AccuracyTable!$C$2:$AF$31, MATCH($A20, AccuracyTable!$B$2:$B$31, 0), MATCH($B$7, AccuracyTable!$C$1:$AF$1, 0))) -> 0.1981 | H20: =IF($B$8="","",INDEX(AccuracyTable!$C$2:$AF$31, MATCH($A20, AccuracyTable!$B$2:$B$31, 0), MATCH($B$8, AccuracyTable!$C$1:$AF$1, 0))) -> 0.3287 | I20: =IF($B$9="","",INDEX(AccuracyTable!$C$2:$AF$31, MATCH($A20, AccuracyTable!$B$2:$B$31, 0), MATCH($B$9, AccuracyTable!$C$1:$AF$1, 0))) -> 0.5005 | J20: =IF($B$10="","",INDEX(AccuracyTable!$C$2:$AF$31, MATCH($A20, AccuracyTable!$B$2:$B$31, 0), MATCH($B$10, AccuracyTable!$C$1:$AF$1, 0))) -> 0.6397 | K20: =IF($B$7="","",F20*G20) -> 5.9080947 | L20: =IF($B$8="","",F20*H20) -> 9.8030829 | M20: =IF($B$9="","",F20*I20) -> 14.926812 | N20: =IF($B$10="","",F20*J20) -> 19.078284
A21: S4 | B21: =INDEX(AccuracyTable!$A$2:$A$31, MATCH($A21, AccuracyTable!$B$2:$B$31, 0)) -> 698 | C21: 0.5 | D21: =B21*C21 -> 349 | E21: =D21/SUM($D$18:$D$24) -> 0.20539077 | F21: =$B$5*E21 -> 14.993526 | G21: =IF($B$7="","",INDEX(AccuracyTable!$C$2:$AF$31, MATCH($A21, AccuracyTable!$B$2:$B$31, 0), MATCH($B$7, AccuracyTable!$C$1:$AF$1, 0))) -> 0.1018 | H21: =IF($B$8="","",INDEX(AccuracyTable!$C$2:$AF$31, MATCH($A21, AccuracyTable!$B$2:$B$31, 0), MATCH($B$8, AccuracyTable!$C$1:$AF$1, 0))) -> 0.1667 | I21: =IF($B$9="","",INDEX(AccuracyTable!$C$2:$AF$31, MATCH($A21, AccuracyTable!$B$2:$B$31, 0), MATCH($B$9, AccuracyTable!$C$1:$AF$1, 0))) -> 0.284 | J21: =IF($B$10="","",INDEX(AccuracyTable!$C$2:$AF$31, MATCH($A21, AccuracyTable!$B$2:$B$31, 0), MATCH($B$10, AccuracyTable!$C$1:$AF$1, 0))) -> 0.4072 | K21: =IF($B$7="","",F21*G21) -> 1.526341 | L21: =IF($B$8="","",F21*H21) -> 2.4994208 | M21: =IF($B$9="","",F21*I21) -> 4.2581615 | N21: =IF($B$10="","",F21*J21) -> 6.1053639
A22: L3 | B22: =INDEX(AccuracyTable!$A$2:$A$31, MATCH($A22, AccuracyTable!$B$2:$B$31, 0)) -> 36 | C22: 1 | D22: =B22*C22 -> 36 | E22: =D22/SUM($D$18:$D$24) -> 0.021186441 | F22: =$B$5*E22 -> 1.5466102 | G22: =IF($B$7="","",INDEX(AccuracyTable!$C$2:$AF$31, MATCH($A22, AccuracyTable!$B$2:$B$31, 0), MATCH($B$7, AccuracyTable!$C$1:$AF$1, 0))) -> 0.4058 | H22: =IF($B$8="","",INDEX(AccuracyTable!$C$2:$AF$31, MATCH($A22, AccuracyTable!$B$2:$B$31, 0), MATCH($B$8, AccuracyTable!$C$1:$AF$1, 0))) -> 0.6996 | I22: =IF($B$9="","",INDEX(AccuracyTable!$C$2:$AF$31, MATCH($A22, AccuracyTable!$B$2:$B$31, 0), MATCH($B$9, AccuracyTable!$C$1:$AF$1, 0))) -> 0.909 | J22: =IF($B$10="","",INDEX(AccuracyTable!$C$2:$AF$31, MATCH($A22, AccuracyTable!$B$2:$B$31, 0), MATCH($B$10, AccuracyTable!$C$1:$AF$1, 0))) -> 0.947 | K22: =IF($B$7="","",F22*G22) -> 0.62761441 | L22: =IF($B$8="","",F22*H22) -> 1.0820085 | M22: =IF($B$9="","",F22*I22) -> 1.4058686 | N22: =IF($B$10="","",F22*J22) -> 1.4646398
A23: L4 | B23: =INDEX(AccuracyTable!$A$2:$A$31, MATCH($A23, AccuracyTable!$B$2:$B$31, 0)) -> 100 | C23: 1 | D23: =B23*C23 -> 100 | E23: =D23/SUM($D$18:$D$24) -> 0.058851224 | F23: =$B$5*E23 -> 4.2961394 | G23: =IF($B$7="","",INDEX(AccuracyTable!$C$2:$AF$31, MATCH($A23, AccuracyTable!$B$2:$B$31, 0), MATCH($B$7, AccuracyTable!$C$1:$AF$1, 0))) -> 0.2103 | H23: =IF($B$8="","",INDEX(AccuracyTable!$C$2:$AF$31, MATCH($A23, AccuracyTable!$B$2:$B$31, 0), MATCH($B$8, AccuracyTable!$C$1:$AF$1, 0))) -> 0.4087 | I23: =IF($B$9="","",INDEX(AccuracyTable!$C$2:$AF$31, MATCH($A23, AccuracyTable!$B$2:$B$31, 0), MATCH($B$9, AccuracyTable!$C$1:$AF$1, 0))) -> 0.7003 | J23: =IF($B$10="","",INDEX(AccuracyTable!$C$2:$AF$31, MATCH($A23, AccuracyTable!$B$2:$B$31, 0), MATCH($B$10, AccuracyTable!$C$1:$AF$1, 0))) -> 0.8737 | K23: =IF($B$7="","",F23*G23) -> 0.90347811 | L23: =IF($B$8="","",F23*H23) -> 1.7558322 | M23: =IF($B$9="","",F23*I23) -> 3.0085864 | N23: =IF($B$10="","",F23*J23) -> 3.753537
A24: L5 | B24: =INDEX(AccuracyTable!$A$2:$A$31, MATCH($A24, AccuracyTable!$B$2:$B$31, 0)) -> 314 | C24: 0.5 | D24: =B24*C24 -> 157 | E24: =D24/SUM($D$18:$D$24) -> 0.092396422 | F24: =$B$5*E24 -> 6.7449388 | G24: =IF($B$7="","",INDEX(AccuracyTable!$C$2:$AF$31, MATCH($A24, AccuracyTable!$B$2:$B$31, 0), MATCH($B$7, AccuracyTable!$C$1:$AF$1, 0))) -> 0.1256 | H24: =IF($B$8="","",INDEX(AccuracyTable!$C$2:$AF$31, MATCH($A24, AccuracyTable!$B$2:$B$31, 0), MATCH($B$8, AccuracyTable!$C$1:$AF$1, 0))) -> 0.2344 | I24: =IF($B$9="","",INDEX(AccuracyTable!$C$2:$AF$31, MATCH($A24, AccuracyTable!$B$2:$B$31, 0), MATCH($B$9, AccuracyTable!$C$1:$AF$1, 0))) -> 0.4516 | J24: =IF($B$10="","",INDEX(AccuracyTable!$C$2:$AF$31, MATCH($A24, AccuracyTable!$B$2:$B$31, 0), MATCH($B$10, AccuracyTable!$C$1:$AF$1, 0))) -> 0.6714 | K24: =IF($B$7="","",F24*G24) -> 0.84716431 | L24: =IF($B$8="","",F24*H24) -> 1.5810137 | M24: =IF($B$9="","",F24*I24) -> 3.0460144 | N24: =IF($B$10="","",F24*J24) -> 4.5285519
A25: TOTAL | D25: =SUM($D$18:$D$24) -> 1699.2 | E25: =SUM($E$18:$E$24) -> 1 | F25: =SUM($F$18:$F$24) -> 73 | K25: =SUM($K$18:$K$24) -> 16.831403 | L25: =SUM($L$18:$L$24) -> 26.666899 | M25: =SUM($M$18:$M$24) -> 39.221046 | N25: =SUM($N$18:$N$24) -> 48.852111
A27: Variance (approx) | K27: =IF($B$7="","",SUMPRODUCT($F$18:$F$24,$G$18:$G$24,(1-$G$18:$G$24))) -> 11.59349 | L27: =IF($B$8="","",SUMPRODUCT($F$18:$F$24,$H$18:$H$24,(1-$H$18:$H$24))) -> 14.659492 | M27: =IF($B$9="","",SUMPRODUCT($F$18:$F$24,$I$18:$I$24,(1-$I$18:$I$24))) -> 15.574573 | N27: =IF($B$10="","",SUMPRODUCT($F$18:$F$24,$J$18:$J$24,(1-$J$18:$J$24))) -> 14.014903
A28: Std dev (approx) | K28: =IF($B$7="","",SQRT(K27)) -> 3.4049215 | L28: =IF($B$8="","",SQRT(L27)) -> 3.8287717 | M28: =IF($B$9="","",SQRT(M27)) -> 3.9464634 | N28: =IF($B$10="","",SQRT(N27)) -> 3.7436483

Sheet Quiz 4
A1: Quiz 4 – Scope, Weights, Thresholds, Pass Probabilities
A3: Controls (blue = editable) | D3: Threshold & pass probabilities
A4: Quiz level (n) | B4: 4 | D4: Pass threshold (expected correct at ability n) | E4: =M26 -> 49.133461
A5: Total questions (N) | B5: 89 | D5: Pass threshold (rounded up) | E5: =ROUNDUP($E$4,0) -> 50
A6: Note: Weight share is proportional to (items × weight).
A7: Ability n-1 | B7: =IF(OR($B$4-1<0.5,$B$4-1>15),"",$B$4-1) -> 3 | D7: P-1 (ability n-1) | E7: =IF($B$7="",-1,IF(K29=0,IF(K26>=$E$5,1,0),1-_xlfn.NORM.DIST($E$5-0.5,K26,K29,TRUE))) -> 3.2907709e-08
A8: Ability n-0.5 | B8: =IF(OR($B$4-0.5<0.5,$B$4-0.5>15),"",$B$4-0.5) -> 3.5 | D8: P-0.5 (ability n-0.5) | E8: =IF($B$8="",-1,IF(L29=0,IF(L26>=$E$5,1,0),1-_xlfn.NORM.DIST($E$5-0.5,L26,L29,TRUE))) -> 0.0032095504
A9: Ability n | B9: =$B$4 -> 4 | D9: P-0 (ability n) | E9: =IF($B$9="",-1,IF(M29=0,IF(M26>=$E$5,1,0),1-_xlfn.NORM.DIST($E$5-0.5,M26,M29,TRUE))) -> 0.46504068
A10: Ability n+0.5 | B10: =IF(OR($B$4+0.5<0.5,$B$4+0.5>15),"",$B$4+0.5) -> 4.5 | D10: P+0.5 (ability n+0.5) | E10: =IF($B$10="",-1,IF(N29=0,IF(N26>=$E$5,1,0),1-_xlfn.NORM.DIST($E$5-0.5,N26,N29,TRUE))) -> 0.99803655
E11: n-1 | F11: n-0.5 | G11: n | H11: n+0.5
D12: Mean correct | E12: =IF($B$7="","",K26) -> 27.751374 | F12: =IF($B$8="","",L26) -> 38.009165 | G12: =IF($B$9="","",M26) -> 49.133461 | H12: =IF($B$10="","",N26) -> 60.711122
D13: Accuracy % | E13: =IF($B$7="","",K26/$B$5) -> 0.31181319 | F13: =IF($B$8="","",L26/$B$5) -> 0.42706927 | G13: =IF($B$9="","",M26/$B$5) -> 0.55206136 | H13: =IF($B$10="","",N26/$B$5) -> 0.68214744
D14: Std dev correct | E14: =IF($B$7="","",K29) -> 4.0258566 | F14: =IF($B$8="","",L29) -> 4.2159419 | G14: =IF($B$9="","",M29) -> 4.1774432 | H14: =IF($B$10="","",N29) -> 3.8873852
A17: Set | B17: Items | C17: Weight (per item) | D17: Items×Weight | E17: Weight share | F17: Expected questions | G17: p(correct) @ n-1 | H17: p(correct) @ n-0.5 | I17: p(correct) @ n | J17: p(correct) @ n+0.5 | K17: Exp correct @ n-1 | L17: Exp correct @ n-0.5 | M17: Exp correct @ n | N17: Exp correct @ n+0.5
A18: S2 | B18: =INDEX(AccuracyTable!$A$2:$A$31, MATCH($A18, AccuracyTable!$B$2:$B$31, 0)) -> 196 | C18: 1 | D18: =B18*C18 -> 196 | E18: =D18/SUM($D$18:$D$25) -> 0.047688564 | F18: =$B$5*E18 -> 4.2442822 | G18: =IF($B$7="","",INDEX(AccuracyTable!$C$2:$AF$31, MATCH($A18, AccuracyTable!$B$2:$B$31, 0), MATCH($B$7, AccuracyTable!$C$1:$AF$1, 0))) -> 0.7751 | H18: =IF($B$8="","",INDEX(AccuracyTable!$C$2:$AF$31, MATCH($A18, AccuracyTable!$B$2:$B$31, 0), MATCH($B$8, AccuracyTable!$C$1:$AF$1, 0))) -> 0.8794 | I18: =IF($B$9="","",INDEX(AccuracyTable!$C$2:$AF$31, MATCH($A18, AccuracyTable!$B$2:$B$31, 0), MATCH($B$9, AccuracyTable!$C$1:$AF$1, 0))) -> 0.9333 | J18: =IF($B$10="","",INDEX(AccuracyTable!$C$2:$AF$31, MATCH($A18, AccuracyTable!$B$2:$B$31, 0), MATCH($B$10, AccuracyTable!$C$1:$AF$1, 0))) -> 0.9491 | K18: =IF($B$7="","",F18*G18) -> 3.2897432 | L18: =IF($B$8="","",F18*H18) -> 3.7324218 | M18: =IF($B$9="","",F18*I18) -> 3.9611886 | N18: =IF($B$10="","",F18*J18) -> 4.0282483
A19: S3 | B19: =INDEX(AccuracyTable!$A$2:$A$31, MATCH($A19, AccuracyTable!$B$2:$B$31, 0)) -> 534 | C19: 1.3 | D19: =B19*C19 -> 694.2 | E19: =D19/SUM($D$18:$D$25) -> 0.16890511 | F19: =$B$5*E19 -> 15.032555 | G19: =IF($B$7="","",INDEX(AccuracyTable!$C$2:$AF$31, MATCH($A19, AccuracyTable!$B$2:$B$31, 0), MATCH($B$7, AccuracyTable!$C$1:$AF$1, 0))) -> 0.5005 | H19: =IF($B$8="","",INDEX(AccuracyTable!$C$2:$AF$31, MATCH($A19, AccuracyTable!$B$2:$B$31, 0), MATCH($B$8, AccuracyTable!$C$1:$AF$1, 0))) -> 0.6397 | I19: =IF($B$9="","",INDEX(AccuracyTable!$C$2:$AF$31, MATCH($A19, AccuracyTable!$B$2:$B$31, 0), MATCH($B$9, AccuracyTable!$C$1:$AF$1, 0))) -> 0.767 | J19: =IF($B$10="","",INDEX(AccuracyTable!$C$2:$AF$31, MATCH($A19, AccuracyTable!$B$2:$B$31, 0), MATCH($B$10, AccuracyTable!$C$1:$AF$1, 0))) -> 0.8732 | K19: =IF($B$7="","",F19*G19) -> 7.5237936 | L19: =IF($B$8="","",F19*H19) -> 9.6163253 | M19: =IF($B$9="","",F19*I19) -> 11.529969 | N19: =IF($B$10="","",F19*J19) -> 13.126427
A20: S4 | B20: =INDEX(AccuracyTable!$A$2:$A$31, MATCH($A20, AccuracyTable!$B$2:$B$31, 0)) -> 698 | C20: 1.5 | D20: =B20*C20 -> 1047 | E20: =D20/SUM($D$18:$D$25) -> 0.25474453 | F20: =$B$5*E20 -> 22.672263 | G20: =IF($B$7="","",INDEX(AccuracyTable!$C$2:$AF$31, MATCH($A20, AccuracyTable!$B$2:$B$31, 0), MATCH($B$7, AccuracyTable!$C$1:$AF$1, 0))) -> 0.284 | H20: =IF($B$8="","",INDEX(AccuracyTable!$C$2:$AF$31, MATCH($A20, AccuracyTable!$B$2:$B$31, 0), MATCH($B$8, AccuracyTable!$C$1:$AF$1, 0))) -> 0.4072 | I20: =IF($B$9="","",INDEX(AccuracyTable!$C$2:$AF$31, MATCH($A20, AccuracyTable!$B$2:$B$31, 0), MATCH($B$9, AccuracyTable!$C$1:$AF$1, 0))) -> 0.5484 | J20: =IF($B$10="","",INDEX(AccuracyTable!$C$2:$AF$31, MATCH($A20, AccuracyTable!$B$2:$B$31, 0), MATCH($B$10, AccuracyTable!$C$1:$AF$1, 0))) -> 0.7052 | K20: =IF($B$7="","",F20*G20) -> 6.4389226 | L20: =IF($B$8="","",F20*H20) -> 9.2321454 | M20: =IF($B$9="","",F20*I20) -> 12.433469 | N20: =IF($B$10="","",F20*J20) -> 15.98848
A21: S5 | B21: =INDEX(AccuracyTable!$A$2:$A$31, MATCH($A21, AccuracyTable!$B$2:$B$31, 0)) -> 1268 | C21: 0.6 | D21: =B21*C21 -> 760.8 | E21: =D21/SUM($D$18:$D$25) -> 0.18510949 | F21: =$B$5*E21 -> 16.474745 | G21: =IF($B$7="","",INDEX(AccuracyTable!$C$2:$AF$31, MATCH($A21, AccuracyTable!$B$2:$B$31, 0), MATCH($B$7, AccuracyTable!$C$1:$AF$1, 0))) -> 0.1761 | H21: =IF($B$8="","",INDEX(AccuracyTable!$C$2:$AF$31, MATCH($A21, AccuracyTable!$B$2:$B$31, 0), MATCH($B$8, AccuracyTable!$C$1:$AF$1, 0))) -> 0.2579 | I21: =IF($B$9="","",INDEX(AccuracyTable!$C$2:$AF$31, MATCH($A21, AccuracyTable!$B$2:$B$31, 0), MATCH($B$9, AccuracyTable!$C$1:$AF$1, 0))) -> 0.3668 | J21: =IF($B$10="","",INDEX(AccuracyTable!$C$2:$AF$31, MATCH($A21, AccuracyTable!$B$2:$B$31, 0), MATCH($B$10, AccuracyTable!$C$1:$AF$1, 0))) -> 0.5118 | K21: =IF($B$7="","",F21*G21) -> 2.9012025 | L21: =IF($B$8="","",F21*H21) -> 4.2488366 | M21: =IF($B$9="","",F21*I21) -> 6.0429363 | N21: =IF($B$10="","",F21*J21) -> 8.4317742
A22: S6 | B22: =INDEX(AccuracyTable!$A$2:$A$31, MATCH($A22, AccuracyTable!$B$2:$B$31, 0)) -> 2021 | C22: 0.3 | D22: =B22*C22 -> 606.3 | E22: =D22/SUM($D$18:$D$25) -> 0.14751825 | F22: =$B$5*E22 -> 13.129124 | G22: =IF($B$7="","",INDEX(AccuracyTable!$C$2:$AF$31, MATCH($A22, AccuracyTable!$B$2:$B$31, 0), MATCH($B$7, AccuracyTable!$C$1:$AF$1, 0))) -> 0.0889 | H22: =IF($B$8="","",INDEX(AccuracyTable!$C$2:$AF$31, MATCH($A22, AccuracyTable!$B$2:$B$31, 0), MATCH($B$8, AccuracyTable!$C$1:$AF$1, 0))) -> 0.123 | I22: =IF($B$9="","",INDEX(AccuracyTable!$C$2:$AF$31, MATCH($A22, AccuracyTable!$B$2:$B$31, 0), MATCH($B$9, AccuracyTable!$C$1:$AF$1, 0))) -> 0.1806 | J22: =IF($B$10="","",INDEX(AccuracyTable!$C$2:$AF$31, MATCH($A22, AccuracyTable!$B$2:$B$31, 0), MATCH($B$10, AccuracyTable!$C$1:$AF$1, 0))) -> 0.2832 | K22: =IF($B$7="","",F22*G22) -> 1.1671791 | L22: =IF($B$8="","",F22*H22) -> 1.6148823 | M22: =IF($B$9="","",F22*I22) -> 2.3711198 | N22: =IF($B$10="","",F22*J22) -> 3.7181679
A23: L4 | B23: =INDEX(AccuracyTable!$A$2:$A$31, MATCH($A23, AccuracyTable!$B$2:$B$31, 0)) -> 100 | C23: 1 | D23: =B23*C23 -> 100 | E23: =D23/SUM($D$18:$D$25) -> 0.0243309 | F23: =$B$5*E23 -> 2.1654501 | G23: =IF($B$7="","",INDEX(AccuracyTable!$C$2:$AF$31, MATCH($A23, AccuracyTable!$B$2:$B$31, 0), MATCH($B$7, AccuracyTable!$C$1:$AF$1, 0))) -> 0.7003 | H23: =IF($B$8="","",INDEX(AccuracyTable!$C$2:$AF$31, MATCH($A23, AccuracyTable!$B$2:$B$31, 0), MATCH($B$8, AccuracyTable!$C$1:$AF$1, 0))) -> 0.8737 | I23: =IF($B$9="","",INDEX(AccuracyTable!$C$2:$AF$31, MATCH($A23, AccuracyTable!$B$2:$B$31, 0), MATCH($B$9, AccuracyTable!$C$1:$AF$1, 0))) -> 0.9405 | J23: =IF($B$10="","",INDEX(AccuracyTable!$C$2:$AF$31, MATCH($A23, AccuracyTable!$B$2:$B$31, 0), MATCH($B$10, AccuracyTable!$C$1:$AF$1, 0))) -> 0.9499 | K23: =IF($B$7="","",F23*G23) -> 1.5164647 | L23: =IF($B$8="","",F23*H23) -> 1.8919538 | M23: =IF($B$9="","",F23*I23) -> 2.0366058 | N23: =IF($B$10="","",F23*J23) -> 2.0569611
A24: L5 | B24: =INDEX(AccuracyTable!$A$2:$A$31, MATCH($A24, AccuracyTable!$B$2:$B$31, 0)) -> 314 | C24: 0.8 | D24: =B24*C24 -> 251.2 | E24: =D24/SUM($D$18:$D$25) -> 0.061119221 | F24: =$B$5*E24 -> 5.4396107 | G24: =IF($B$7="","",INDEX(AccuracyTable!$C$2:$AF$31, MATCH($A24, AccuracyTable!$B$2:$B$31, 0), MATCH($B$7, AccuracyTable!$C$1:$AF$1, 0))) -> 0.4516 | H24: =IF($B$8="","",INDEX(AccuracyTable!$C$2:$AF$31, MATCH($A24, AccuracyTable!$B$2:$B$31, 0), MATCH($B$8, AccuracyTable!$C$1:$AF$1, 0))) -> 0.6714 | I24: =IF($B$9="","",INDEX(AccuracyTable!$C$2:$AF$31, MATCH($A24, AccuracyTable!$B$2:$B$31, 0), MATCH($B$9, AccuracyTable!$C$1:$AF$1, 0))) -> 0.8538 | J24: =IF($B$10="","",INDEX(AccuracyTable!$C$2:$AF$31, MATCH($A24, AccuracyTable!$B$2:$B$31, 0), MATCH($B$10, AccuracyTable!$C$1:$AF$1, 0))) -> 0.9386 | K24: =IF($B$7="","",F24*G24) -> 2.4565282 | L24: =IF($B$8="","",F24*H24) -> 3.6521546 | M24: =IF($B$9="","",F24*I24) -> 4.6443396 | N24: =IF($B$10="","",F24*J24) -> 5.1056186
A25: L6 | B25: =INDEX(AccuracyTable!$A$2:$A$31, MATCH($A25, AccuracyTable!$B$2:$B$31, 0)) -> 909 | C25: 0.5 | D25: =B25*C25 -> 454.5 | E25: =D25/SUM($D$18:$D$25) -> 0.11058394 | F25: =$B$5*E25 -> 9.8419708 | G25: =IF($B$7="","",INDEX(AccuracyTable!$C$2:$AF$31, MATCH($A25, AccuracyTable!$B$2:$B$31, 0), MATCH($B$7, AccuracyTable!$C$1:$AF$1, 0))) -> 0.2497 | H25: =IF($B$8="","",INDEX(AccuracyTable!$C$2:$AF$31, MATCH($A25, AccuracyTable!$B$2:$B$31, 0), MATCH($B$8, AccuracyTable!$C$1:$AF$1, 0))) -> 0.4085 | I25: =IF($B$9="","",INDEX(AccuracyTable!$C$2:$AF$31, MATCH($A25, AccuracyTable!$B$2:$B$31, 0), MATCH($B$9, AccuracyTable!$C$1:$AF$1, 0))) -> 0.6212 | J25: =IF($B$10="","",INDEX(AccuracyTable!$C$2:$AF$31, MATCH($A25, AccuracyTable!$B$2:$B$31, 0), MATCH($B$10, AccuracyTable!$C$1:$AF$1, 0))) -> 0.8388 | K25: =IF($B$7="","",F25*G25) -> 2.4575401 | L25: =IF($B$8="","",F25*H25) -> 4.0204451 | M25: =IF($B$9="","",F25*I25) -> 6.1138323 | N25: =IF($B$10="","",F25*J25) -> 8.2554451
A26: TOTAL | D26: =SUM($D$18:$D$25) -> 4110 | E26: =SUM($E$18:$E$25) -> 1 | F26: =SUM($F$18:$F$25) -> 89 | K26: =SUM($K$18:$K$25) -> 27.751374 | L26: =SUM($L$18:$L$25) -> 38.009165 | M26: =SUM($M$18:$M$25) -> 49.133461 | N26: =SUM($N$18:$N$25) -> 60.711122
A28: Variance (approx) | K28: =IF($B$7="","",SUMPRODUCT($F$18:$F$25,$G$18:$G$25,(1-$G$18:$G$25))) -> 16.207521 | L28: =IF($B$8="","",SUMPRODUCT($F$18:$F$25,$H$18:$H$25,(1-$H$18:$H$25))) -> 17.774166 | M28: =IF($B$9="","",SUMPRODUCT($F$18:$F$25,$I$18:$I$25,(1-$I$18:$I$25))) -> 17.451032 | N28: =IF($B$10="","",SUMPRODUCT($F$18:$F$25,$J$18:$J$25,(1-$J$18:$J$25))) -> 15.111764
A29: Std dev (approx) | K29: =IF($B$7="","",SQRT(K28)) -> 4.0258566 | L29: =IF($B$8="","",SQRT(L28)) -> 4.2159419 | M29: =IF($B$9="","",SQRT(M28)) -> 4.1774432 | N29: =IF($B$10="","",SQRT(N28)) -> 3.8873852

Sheet Quiz 5
A1: Quiz 5 – Scope, Weights, Thresholds, Pass Probabilities
A3: Controls (blue = editable) | D3: Threshold & pass probabilities
A4: Quiz level (n) | B4: 5 | D4: Pass threshold (expected correct at ability n) | E4: =M26 -> 59.142632
A5: Total questions (N) | B5: 98 | D5: Pass threshold (rounded up) | E5: =ROUNDUP($E$4,0) -> 60
A6: Note: Weight share is proportional to (items × weight).
A7: Ability n-1 | B7: =IF(OR($B$4-1<0.5,$B$4-1>15),"",$B$4-1) -> 4 | D7: P-1 (ability n-1) | E7: =IF($B$7="",-1,IF(K29=0,IF(K26>=$E$5,1,0),1-_xlfn.NORM.DIST($E$5-0.5,K26,K29,TRUE))) -> 1.4634328e-09
A8: Ability n-0.5 | B8: =IF(OR($B$4-0.5<0.5,$B$4-0.5>15),"",$B$4-0.5) -> 4.5 | D8: P-0.5 (ability n-0.5) | E8: =IF($B$8="",-1,IF(L29=0,IF(L26>=$E$5,1,0),1-_xlfn.NORM.DIST($E$5-0.5,L26,L29,TRUE))) -> 0.0017474655
A9: Ability n | B9: =$B$4 -> 5 | D9: P-0 (ability n) | E9: =IF($B$9="",-1,IF(M29=0,IF(M26>=$E$5,1,0),1-_xlfn.NORM.DIST($E$5-0.5,M26,M29,TRUE))) -> 0.46622695
A10: Ability n+0.5 | B10: =IF(OR($B$4+0.5<0.5,$B$4+0.5>15),"",$B$4+0.5) -> 5.5 | D10: P+0.5 (ability n+0.5) | E10: =IF($B$10="",-1,IF(N29=0,IF(N26>=$E$5,1,0),1-_xlfn.NORM.DIST($E$5-0.5,N26,N29,TRUE))) -> 0.99590691
E11: n-1 | F11: n-0.5 | G11: n | H11: n+0.5
D12: Mean correct | E12: =IF($B$7="","",K26) -> 34.539072 | F12: =IF($B$8="","",L26) -> 46.947417 | G12: =IF($B$9="","",M26) -> 59.142632 | H12: =IF($B$10="","",N26) -> 70.066122
D13: Accuracy % | E13: =IF($B$7="","",K26/$B$5) -> 0.35243951 | F13: =IF($B$8="","",L26/$B$5) -> 0.47905528 | G13: =IF($B$9="","",M26/$B$5) -> 0.60349624 | H13: =IF($B$10="","",N26/$B$5) -> 0.71496043
D14: Std dev correct | E14: =IF($B$7="","",K29) -> 4.2052573 | F14: =IF($B$8="","",L29) -> 4.2981239 | G14: =IF($B$9="","",M29) -> 4.2163431 | H14: =IF($B$10="","",N29) -> 3.9958212
A17: Set | B17: Items | C17: Weight (per item) | D17: Items×Weight | E17: Weight share | F17: Expected questions | G17: p(correct) @ n-1 | H17: p(correct) @ n-0.5 | I17: p(correct) @ n | J17: p(correct) @ n+0.5 | K17: Exp correct @ n-1 | L17: Exp correct @ n-0.5 | M17: Exp correct @ n | N17: Exp correct @ n+0.5
A18: S3 | B18: =INDEX(AccuracyTable!$A$2:$A$31, MATCH($A18, AccuracyTable!$B$2:$B$31, 0)) -> 534 | C18: 1 | D18: =B18*C18 -> 534 | E18: =D18/SUM($D$18:$D$25) -> 0.060988145 | F18: =$B$5*E18 -> 5.9768382 | G18: =IF($B$7="","",INDEX(AccuracyTable!$C$2:$AF$31, MATCH($A18, AccuracyTable!$B$2:$B$31, 0), MATCH($B$7, AccuracyTable!$C$1:$AF$1, 0))) -> 0.767 | H18: =IF($B$8="","",INDEX(AccuracyTable!$C$2:$AF$31, MATCH($A18, AccuracyTable!$B$2:$B$31, 0), MATCH($B$8, AccuracyTable!$C$1:$AF$1, 0))) -> 0.8732 | I18: =IF($B$9="","",INDEX(AccuracyTable!$C$2:$AF$31, MATCH($A18, AccuracyTable!$B$2:$B$31, 0), MATCH($B$9, AccuracyTable!$C$1:$AF$1, 0))) -> 0.9301 | J18: =IF($B$10="","",INDEX(AccuracyTable!$C$2:$AF$31, MATCH($A18, AccuracyTable!$B$2:$B$31, 0), MATCH($B$10, AccuracyTable!$C$1:$AF$1, 0))) -> 0.9484 | K18: =IF($B$7="","",F18*G18) -> 4.5842349 | L18: =IF($B$8="","",F18*H18) -> 5.2189751 | M18: =IF($B$9="","",F18*I18) -> 5.5590572 | N18: =IF($B$10="","",F18*J18) -> 5.6684334
A19: S4 | B19: =INDEX(AccuracyTable!$A$2:$A$31, MATCH($A19, AccuracyTable!$B$2:$B$31, 0)) -> 698 | C19: 1.3 | D19: =B19*C19 -> 907.4 | E19: =D19/SUM($D$18:$D$25) -> 0.10363416 | F19: =$B$5*E19 -> 10.156148 | G19: =IF($B$7="","",INDEX(AccuracyTable!$C$2:$AF$31, MATCH($A19, AccuracyTable!$B$2:$B$31, 0), MATCH($B$7, AccuracyTable!$C$1:$AF$1, 0))) -> 0.5484 | H19: =IF($B$8="","",INDEX(AccuracyTable!$C$2:$AF$31, MATCH($A19, AccuracyTable!$B$2:$B$31, 0), MATCH($B$8, AccuracyTable!$C$1:$AF$1, 0))) -> 0.7052 | I19: =IF($B$9="","",INDEX(AccuracyTable!$C$2:$AF$31, MATCH($A19, AccuracyTable!$B$2:$B$31, 0), MATCH($B$9, AccuracyTable!$C$1:$AF$1, 0))) -> 0.8333 | J19: =IF($B$10="","",INDEX(AccuracyTable!$C$2:$AF$31, MATCH($A19, AccuracyTable!$B$2:$B$31, 0), MATCH($B$10, AccuracyTable!$C$1:$AF$1, 0))) -> 0.9171 | K19: =IF($B$7="","",F19*G19) -> 5.5696315 | L19: =IF($B$8="","",F19*H19) -> 7.1621155 | M19: =IF($B$9="","",F19*I19) -> 8.4631181 | N19: =IF($B$10="","",F19*J19) -> 9.3142033
A20: S5 | B20: =INDEX(AccuracyTable!$A$2:$A$31, MATCH($A20, AccuracyTable!$B$2:$B$31, 0)) -> 1268 | C20: 1.5 | D20: =B20*C20 -> 1902 | E20: =D20/SUM($D$18:$D$25) -> 0.21722744 | F20: =$B$5*E20 -> 21.288289 | G20: =IF($B$7="","",INDEX(AccuracyTable!$C$2:$AF$31, MATCH($A20, AccuracyTable!$B$2:$B$31, 0), MATCH($B$7, AccuracyTable!$C$1:$AF$1, 0))) -> 0.3668 | H20: =IF($B$8="","",INDEX(AccuracyTable!$C$2:$AF$31, MATCH($A20, AccuracyTable!$B$2:$B$31, 0), MATCH($B$8, AccuracyTable!$C$1:$AF$1, 0))) -> 0.5118 | I20: =IF($B$9="","",INDEX(AccuracyTable!$C$2:$AF$31, MATCH($A20, AccuracyTable!$B$2:$B$31, 0), MATCH($B$9, AccuracyTable!$C$1:$AF$1, 0))) -> 0.6564 | J20: =IF($B$10="","",INDEX(AccuracyTable!$C$2:$AF$31, MATCH($A20, AccuracyTable!$B$2:$B$31, 0), MATCH($B$10, AccuracyTable!$C$1:$AF$1, 0))) -> 0.7871 | K20: =IF($B$7="","",F20*G20) -> 7.8085444 | L20: =IF($B$8="","",F20*H20) -> 10.895346 | M20: =IF($B$9="","",F20*I20) -> 13.973633 | N20: =IF($B$10="","",F20*J20) -> 16.756012
A21: S6 | B21: =INDEX(AccuracyTable!$A$2:$A$31, MATCH($A21, AccuracyTable!$B$2:$B$31, 0)) -> 2021 | C21: 1.2 | D21: =B21*C21 -> 2425.2 | E21: =D21/SUM($D$18:$D$25) -> 0.27698211 | F21: =$B$5*E21 -> 27.144247 | G21: =IF($B$7="","",INDEX(AccuracyTable!$C$2:$AF$31, MATCH($A21, AccuracyTable!$B$2:$B$31, 0), MATCH($B$7, AccuracyTable!$C$1:$AF$1, 0))) -> 0.1806 | H21: =IF($B$8="","",INDEX(AccuracyTable!$C$2:$AF$31, MATCH($A21, AccuracyTable!$B$2:$B$31, 0), MATCH($B$8, AccuracyTable!$C$1:$AF$1, 0))) -> 0.2832 | I21: =IF($B$9="","",INDEX(AccuracyTable!$C$2:$AF$31, MATCH($A21, AccuracyTable!$B$2:$B$31, 0), MATCH($B$9, AccuracyTable!$C$1:$AF$1, 0))) -> 0.4197 | J21: =IF($B$10="","",INDEX(AccuracyTable!$C$2:$AF$31, MATCH($A21, AccuracyTable!$B$2:$B$31, 0), MATCH($B$10, AccuracyTable!$C$1:$AF$1, 0))) -> 0.5693 | K21: =IF($B$7="","",F21*G21) -> 4.9022511 | L21: =IF($B$8="","",F21*H21) -> 7.6872508 | M21: =IF($B$9="","",F21*I21) -> 11.392441 | N21: =IF($B$10="","",F21*J21) -> 15.45322
A22: S7 | B22: =INDEX(AccuracyTable!$A$2:$A$31, MATCH($A22, AccuracyTable!$B$2:$B$31, 0)) -> 2806 | C22: 0.5 | D22: =B22*C22 -> 1403 | E22: =D22/SUM($D$18:$D$25) -> 0.16023664 | F22: =$B$5*E22 -> 15.703191 | G22: =IF($B$7="","",INDEX(AccuracyTable!$C$2:$AF$31, MATCH($A22, AccuracyTable!$B$2:$B$31, 0), MATCH($B$7, AccuracyTable!$C$1:$AF$1, 0))) -> 0.102 | H22: =IF($B$8="","",INDEX(AccuracyTable!$C$2:$AF$31, MATCH($A22, AccuracyTable!$B$2:$B$31, 0), MATCH($B$8, AccuracyTable!$C$1:$AF$1, 0))) -> 0.1563 | I22: =IF($B$9="","",INDEX(AccuracyTable!$C$2:$AF$31, MATCH($A22, AccuracyTable!$B$2:$B$31, 0), MATCH($B$9, AccuracyTable!$C$1:$AF$1, 0))) -> 0.2499 | J22: =IF($B$10="","",INDEX(AccuracyTable!$C$2:$AF$31, MATCH($A22, AccuracyTable!$B$2:$B$31, 0), MATCH($B$10, AccuracyTable!$C$1:$AF$1, 0))) -> 0.391 | K22: =IF($B$7="","",F22*G22) -> 1.6017255 | L22: =IF($B$8="","",F22*H22) -> 2.4544088 | M22: =IF($B$9="","",F22*I22) -> 3.9242274 | N22: =IF($B$10="","",F22*J22) -> 6.1399477
A23: L5 | B23: =INDEX(AccuracyTable!$A$2:$A$31, MATCH($A23, AccuracyTable!$B$2:$B$31, 0)) -> 314 | C23: 1 | D23: =B23*C23 -> 314 | E23: =D23/SUM($D$18:$D$25) -> 0.035861943 | F23: =$B$5*E23 -> 3.5144704 | G23: =IF($B$7="","",INDEX(AccuracyTable!$C$2:$AF$31, MATCH($A23, AccuracyTable!$B$2:$B$31, 0), MATCH($B$7, AccuracyTable!$C$1:$AF$1, 0))) -> 0.8538 | H23: =IF($B$8="","",INDEX(AccuracyTable!$C$2:$AF$31, MATCH($A23, AccuracyTable!$B$2:$B$31, 0), MATCH($B$8, AccuracyTable!$C$1:$AF$1, 0))) -> 0.9386 | I23: =IF($B$9="","",INDEX(AccuracyTable!$C$2:$AF$31, MATCH($A23, AccuracyTable!$B$2:$B$31, 0), MATCH($B$9, AccuracyTable!$C$1:$AF$1, 0))) -> 0.9498 | J23: =IF($B$10="","",INDEX(AccuracyTable!$C$2:$AF$31, MATCH($A23, AccuracyTable!$B$2:$B$31, 0), MATCH($B$10, AccuracyTable!$C$1:$AF$1, 0))) -> 0.95 | K23: =IF($B$7="","",F23*G23) -> 3.0006548 | L23: =IF($B$8="","",F23*H23) -> 3.2986819 | M23: =IF($B$9="","",F23*I23) -> 3.338044 | N23: =IF($B$10="","",F23*J23) -> 3.3387469
A24: L6 | B24: =INDEX(AccuracyTable!$A$2:$A$31, MATCH($A24, AccuracyTable!$B$2:$B$31, 0)) -> 909 | C24: 0.8 | D24: =B24*C24 -> 727.2 | E24: =D24/SUM($D$18:$D$25) -> 0.083053519 | F24: =$B$5*E24 -> 8.1392448 | G24: =IF($B$7="","",INDEX(AccuracyTable!$C$2:$AF$31, MATCH($A24, AccuracyTable!$B$2:$B$31, 0), MATCH($B$7, AccuracyTable!$C$1:$AF$1, 0))) -> 0.6212 | H24: =IF($B$8="","",INDEX(AccuracyTable!$C$2:$AF$31, MATCH($A24, AccuracyTable!$B$2:$B$31, 0), MATCH($B$8, AccuracyTable!$C$1:$AF$1, 0))) -> 0.8388 | I24: =IF($B$9="","",INDEX(AccuracyTable!$C$2:$AF$31, MATCH($A24, AccuracyTable!$B$2:$B$31, 0), MATCH($B$9, AccuracyTable!$C$1:$AF$1, 0))) -> 0.9352 | J24: =IF($B$10="","",INDEX(AccuracyTable!$C$2:$AF$31, MATCH($A24, AccuracyTable!$B$2:$B$31, 0), MATCH($B$10, AccuracyTable!$C$1:$AF$1, 0))) -> 0.9498 | K24: =IF($B$7="","",F24*G24) -> 5.0560989 | L24: =IF($B$8="","",F24*H24) -> 6.8271986 | M24: =IF($B$9="","",F24*I24) -> 7.6118218 | N24: =IF($B$10="","",F24*J24) -> 7.7306548
A25: L7 | B25: =INDEX(AccuracyTable!$A$2:$A$31, MATCH($A25, AccuracyTable!$B$2:$B$31, 0)) -> 1086 | C25: 0.5 | D25: =B25*C25 -> 543 | E25: =D25/SUM($D$18:$D$25) -> 0.062016035 | F25: =$B$5*E25 -> 6.0775714 | G25: =IF($B$7="","",INDEX(AccuracyTable!$C$2:$AF$31, MATCH($A25, AccuracyTable!$B$2:$B$31, 0), MATCH($B$7, AccuracyTable!$C$1:$AF$1, 0))) -> 0.3317 | H25: =IF($B$8="","",INDEX(AccuracyTable!$C$2:$AF$31, MATCH($A25, AccuracyTable!$B$2:$B$31, 0), MATCH($B$8, AccuracyTable!$C$1:$AF$1, 0))) -> 0.56 | I25: =IF($B$9="","",INDEX(AccuracyTable!$C$2:$AF$31, MATCH($A25, AccuracyTable!$B$2:$B$31, 0), MATCH($B$9, AccuracyTable!$C$1:$AF$1, 0))) -> 0.803 | J25: =IF($B$10="","",INDEX(AccuracyTable!$C$2:$AF$31, MATCH($A25, AccuracyTable!$B$2:$B$31, 0), MATCH($B$10, AccuracyTable!$C$1:$AF$1, 0))) -> 0.9321 | K25: =IF($B$7="","",F25*G25) -> 2.0159304 | L25: =IF($B$8="","",F25*H25) -> 3.40344 | M25: =IF($B$9="","",F25*I25) -> 4.8802899 | N25: =IF($B$10="","",F25*J25) -> 5.6649043
A26: TOTAL | D26: =SUM($D$18:$D$25) -> 8755.8 | E26: =SUM($E$18:$E$25) -> 1 | F26: =SUM($F$18:$F$25) -> 98 | K26: =SUM($K$18:$K$25) -> 34.539072 | L26: =SUM($L$18:$L$25) -> 46.947417 | M26: =SUM($M$18:$M$25) -> 59.142632 | N26: =SUM($N$18:$N$25) -> 70.066122
A28: Variance (approx) | K28: =IF($B$7="","",SUMPRODUCT($F$18:$F$25,$G$18:$G$25,(1-$G$18:$G$25))) -> 17.684189 | L28: =IF($B$8="","",SUMPRODUCT($F$18:$F$25,$H$18:$H$25,(1-$H$18:$H$25))) -> 18.473869 | M28: =IF($B$9="","",SUMPRODUCT($F$18:$F$25,$I$18:$I$25,(1-$I$18:$I$25))) -> 17.777549 | N28: =IF($B$10="","",SUMPRODUCT($F$18:$F$25,$J$18:$J$25,(1-$J$18:$J$25))) -> 15.966587
A29: Std dev (approx) | K29: =IF($B$7="","",SQRT(K28)) -> 4.2052573 | L29: =IF($B$8="","",SQRT(L28)) -> 4.2981239 | M29: =IF($B$9="","",SQRT(M28)) -> 4.2163431 | N29: =IF($B$10="","",SQRT(N28)) -> 3.9958212

Sheet Quiz 6
A1: Quiz 6 – Scope, Weights, Thresholds, Pass Probabilities
A3: Controls (blue = editable) | D3: Threshold & pass probabilities
A4: Quiz level (n) | B4: 6 | D4: Pass threshold (expected correct at ability n) | E4: =M27 -> 69.577577
A5: Total questions (N) | B5: 113 | D5: Pass threshold (rounded up) | E5: =ROUNDUP($E$4,0) -> 70
A6: Note: Weight share is proportional to (items × weight).
A7: Ability n-1 | B7: =IF(OR($B$4-1<0.5,$B$4-1>15),"",$B$4-1) -> 5 | D7: P-1 (ability n-1) | E7: =IF($B$7="",-1,IF(K30=0,IF(K27>=$E$5,1,0),1-_xlfn.NORM.DIST($E$5-0.5,K27,K30,TRUE))) -> 7.471731e-10
A8: Ability n-0.5 | B8: =IF(OR($B$4-0.5<0.5,$B$4-0.5>15),"",$B$4-0.5) -> 5.5 | D8: P-0.5 (ability n-0.5) | E8: =IF($B$8="",-1,IF(L30=0,IF(L27>=$E$5,1,0),1-_xlfn.NORM.DIST($E$5-0.5,L27,L30,TRUE))) -> 0.0021904291
A9: Ability n | B9: =$B$4 -> 6 | D9: P-0 (ability n) | E9: =IF($B$9="",-1,IF(M30=0,IF(M27>=$E$5,1,0),1-_xlfn.NORM.DIST($E$5-0.5,M27,M30,TRUE))) -> 0.50676145
A10: Ability n+0.5 | B10: =IF(OR($B$4+0.5<0.5,$B$4+0.5>15),"",$B$4+0.5) -> 6.5 | D10: P+0.5 (ability n+0.5) | E10: =IF($B$10="",-1,IF(N30=0,IF(N27>=$E$5,1,0),1-_xlfn.NORM.DIST($E$5-0.5,N27,N30,TRUE))) -> 0.99112549
E11: n-1 | F11: n-0.5 | G11: n | H11: n+0.5
D12: Mean correct | E12: =IF($B$7="","",K27) -> 43.050416 | F12: =IF($B$8="","",L27) -> 56.595404 | G12: =IF($B$9="","",M27) -> 69.577577 | H12: =IF($B$10="","",N27) -> 79.999539
D13: Accuracy % | E13: =IF($B$7="","",K27/$B$5) -> 0.38097713 | F13: =IF($B$8="","",L27/$B$5) -> 0.50084429 | G13: =IF($B$9="","",M27/$B$5) -> 0.61573077 | H13: =IF($B$10="","",N27/$B$5) -> 0.70796052
D14: Std dev correct | E14: =IF($B$7="","",K30) -> 4.3754674 | F14: =IF($B$8="","",L30) -> 4.5289603 | G14: =IF($B$9="","",M30) -> 4.5770235 | H14: =IF($B$10="","",N30) -> 4.4286665
A17: Set | B17: Items | C17: Weight (per item) | D17: Items×Weight | E17: Weight share | F17: Expected questions | G17: p(correct) @ n-1 | H17: p(correct) @ n-0.5 | I17: p(correct) @ n | J17: p(correct) @ n+0.5 | K17: Exp correct @ n-1 | L17: Exp correct @ n-0.5 | M17: Exp correct @ n | N17: Exp correct @ n+0.5
A18: S4 | B18: =INDEX(AccuracyTable!$A$2:$A$31, MATCH($A18, AccuracyTable!$B$2:$B$31, 0)) -> 698 | C18: 1 | D18: =B18*C18 -> 698 | E18: =D18/SUM($D$18:$D$26) -> 0.038513745 | F18: =$B$5*E18 -> 4.3520531 | G18: =IF($B$7="","",INDEX(AccuracyTable!$C$2:$AF$31, MATCH($A18, AccuracyTable!$B$2:$B$31, 0), MATCH($B$7, AccuracyTable!$C$1:$AF$1, 0))) -> 0.8333 | H18: =IF($B$8="","",INDEX(AccuracyTable!$C$2:$AF$31, MATCH($A18, AccuracyTable!$B$2:$B$31, 0), MATCH($B$8, AccuracyTable!$C$1:$AF$1, 0))) -> 0.9171 | I18: =IF($B$9="","",INDEX(AccuracyTable!$C$2:$AF$31, MATCH($A18, AccuracyTable!$B$2:$B$31, 0), MATCH($B$9, AccuracyTable!$C$1:$AF$1, 0))) -> 0.9465 | J18: =IF($B$10="","",INDEX(AccuracyTable!$C$2:$AF$31, MATCH($A18, AccuracyTable!$B$2:$B$31, 0), MATCH($B$10, AccuracyTable!$C$1:$AF$1, 0))) -> 0.9499 | K18: =IF($B$7="","",F18*G18) -> 3.6265659 | L18: =IF($B$8="","",F18*H18) -> 3.9912679 | M18: =IF($B$9="","",F18*I18) -> 4.1192183 | N18: =IF($B$10="","",F18*J18) -> 4.1340153
A19: S5 | B19: =INDEX(AccuracyTable!$A$2:$A$31, MATCH($A19, AccuracyTable!$B$2:$B$31, 0)) -> 1268 | C19: 1.3 | D19: =B19*C19 -> 1648.4 | E19: =D19/SUM($D$18:$D$26) -> 0.090954236 | F19: =$B$5*E19 -> 10.277829 | G19: =IF($B$7="","",INDEX(AccuracyTable!$C$2:$AF$31, MATCH($A19, AccuracyTable!$B$2:$B$31, 0), MATCH($B$7, AccuracyTable!$C$1:$AF$1, 0))) -> 0.6564 | H19: =IF($B$8="","",INDEX(AccuracyTable!$C$2:$AF$31, MATCH($A19, AccuracyTable!$B$2:$B$31, 0), MATCH($B$8, AccuracyTable!$C$1:$AF$1, 0))) -> 0.7871 | I19: =IF($B$9="","",INDEX(AccuracyTable!$C$2:$AF$31, MATCH($A19, AccuracyTable!$B$2:$B$31, 0), MATCH($B$9, AccuracyTable!$C$1:$AF$1, 0))) -> 0.8826 | J19: =IF($B$10="","",INDEX(AccuracyTable!$C$2:$AF$31, MATCH($A19, AccuracyTable!$B$2:$B$31, 0), MATCH($B$10, AccuracyTable!$C$1:$AF$1, 0))) -> 0.9313 | K19: =IF($B$7="","",F19*G19) -> 6.7463667 | L19: =IF($B$8="","",F19*H19) -> 8.0896789 | M19: =IF($B$9="","",F19*I19) -> 9.0712116 | N19: =IF($B$10="","",F19*J19) -> 9.5717418
A20: S6 | B20: =INDEX(AccuracyTable!$A$2:$A$31, MATCH($A20, AccuracyTable!$B$2:$B$31, 0)) -> 2021 | C20: 1.5 | D20: =B20*C20 -> 3031.5 | E20: =D20/SUM($D$18:$D$26) -> 0.16726994 | F20: =$B$5*E20 -> 18.901503 | G20: =IF($B$7="","",INDEX(AccuracyTable!$C$2:$AF$31, MATCH($A20, AccuracyTable!$B$2:$B$31, 0), MATCH($B$7, AccuracyTable!$C$1:$AF$1, 0))) -> 0.4197 | H20: =IF($B$8="","",INDEX(AccuracyTable!$C$2:$AF$31, MATCH($A20, AccuracyTable!$B$2:$B$31, 0), MATCH($B$8, AccuracyTable!$C$1:$AF$1, 0))) -> 0.5693 | I20: =IF($B$9="","",INDEX(AccuracyTable!$C$2:$AF$31, MATCH($A20, AccuracyTable!$B$2:$B$31, 0), MATCH($B$9, AccuracyTable!$C$1:$AF$1, 0))) -> 0.7008 | J20: =IF($B$10="","",INDEX(AccuracyTable!$C$2:$AF$31, MATCH($A20, AccuracyTable!$B$2:$B$31, 0), MATCH($B$10, AccuracyTable!$C$1:$AF$1, 0))) -> 0.8035 | K20: =IF($B$7="","",F20*G20) -> 7.9329608 | L20: =IF($B$8="","",F20*H20) -> 10.760626 | M20: =IF($B$9="","",F20*I20) -> 13.246173 | N20: =IF($B$10="","",F20*J20) -> 15.187358
A21: S7 | B21: =INDEX(AccuracyTable!$A$2:$A$31, MATCH($A21, AccuracyTable!$B$2:$B$31, 0)) -> 2806 | C21: 1.3 | D21: =B21*C21 -> 3647.8 | E21: =D21/SUM($D$18:$D$26) -> 0.2012757 | F21: =$B$5*E21 -> 22.744154 | G21: =IF($B$7="","",INDEX(AccuracyTable!$C$2:$AF$31, MATCH($A21, AccuracyTable!$B$2:$B$31, 0), MATCH($B$7, AccuracyTable!$C$1:$AF$1, 0))) -> 0.2499 | H21: =IF($B$8="","",INDEX(AccuracyTable!$C$2:$AF$31, MATCH($A21, AccuracyTable!$B$2:$B$31, 0), MATCH($B$8, AccuracyTable!$C$1:$AF$1, 0))) -> 0.391 | I21: =IF($B$9="","",INDEX(AccuracyTable!$C$2:$AF$31, MATCH($A21, AccuracyTable!$B$2:$B$31, 0), MATCH($B$9, AccuracyTable!$C$1:$AF$1, 0))) -> 0.5405 | J21: =IF($B$10="","",INDEX(AccuracyTable!$C$2:$AF$31, MATCH($A21, AccuracyTable!$B$2:$B$31, 0), MATCH($B$10, AccuracyTable!$C$1:$AF$1, 0))) -> 0.6589 | K21: =IF($B$7="","",F21*G21) -> 5.6837641 | L21: =IF($B$8="","",F21*H21) -> 8.8929642 | M21: =IF($B$9="","",F21*I21) -> 12.293215 | N21: =IF($B$10="","",F21*J21) -> 14.986123
